<?xml version="1.0"?>
<sdf version="1.6">
  <world name="default">

    <include>
      <uri>model://ground_plane</uri>
    </include>

    <include>
      <uri>model://sun</uri>
    </include>

    <scene>
      <shadows>false</shadows>
    </scene>

    <gui fullscreen='0'>
      <camera name='user_camera'>
        <pose frame=''>0.319654 -0.235002 9.29441 0 1.5138 0.009599</pose>
        <view_controller>orbit</view_controller>
        <projection_type>perspective</projection_type>
      </camera>
    </gui>

    <physics type="ode">
      <real_time_update_rate>1000.0</real_time_update_rate>
      <max_step_size>0.001</max_step_size>
      <real_time_factor>1</real_time_factor>
      <ode>
        <solver>
          <type>quick</type>
          <iters>150</iters>
          <precon_iters>0</precon_iters>
          <sor>1.400000</sor>
          <use_dynamic_moi_rescaling>1</use_dynamic_moi_rescaling>
        </solver>
        <constraints>
          <cfm>0.00001</cfm>
          <erp>0.2</erp>
          <contact_max_correcting_vel>2000.000000</contact_max_correcting_vel>
          <contact_surface_layer>0.01000</contact_surface_layer>
        </constraints>
      </ode>
    </physics>

    <model name="big_turtlebot3_world">
      <static>1</static>
      <include>
        <uri>model://big_turtlebot3_world</uri>
      </include>
    </model>
    
    <model name='sam_bot'>

        <pose>-20.5 -0.5 0.01 0.0 0.0 0.0</pose>

        <link name='base_footprint'>
        <inertial>
            <pose>0.964787 0 1.11848 0 -0 0</pose>
            <mass>1101.35</mass>
            <inertia>
            <ixx>1426.73</ixx>
            <ixy>8.65683e-13</ixy>
            <ixz>-1183.41</ixz>
            <iyy>8937.11</iyy>
            <iyz>5.04871e-28</iyz>
            <izz>9575.33</izz>
            </inertia>
        </inertial>
        <collision name='base_footprint_fixed_joint_lump__cabin_link_collision'>
            <pose>3.8205 0 2.095 0 -0 0</pose>
            <geometry>
            <box>
                <size>1.964 2.14 1.833</size>
            </box>
            </geometry>
        </collision>
        <collision name='base_footprint_fixed_joint_lump__lidar_link_collision_1'>
            <pose>4.7825 0 3.122 0 -0 0</pose>
            <geometry>
            <cylinder>
                <length>0.15</length>
                <radius>0.108</radius>
            </cylinder>
            </geometry>
            <surface>
            <contact>
                <ode/>
            </contact>
            <friction>
                <ode/>
            </friction>
            </surface>
        </collision>
        <collision name='base_footprint_fixed_joint_lump__first_shaft_horizontal_shaft_link_collision_2'>
            <pose>3.302 0 0.536 -1.5708 1.5708 0</pose>
            <geometry>
            <cylinder>
                <length>2.548</length>
                <radius>0.0536</radius>
            </cylinder>
            </geometry>
        </collision>
        <collision name='base_footprint_fixed_joint_lump__fourth_shaft_horizontal_shaft_link_collision_3'>
            <pose>-3.502 0 0.536 -1.5708 1.5708 0</pose>
            <geometry>
            <cylinder>
                <length>2.548</length>
                <radius>0.0536</radius>
            </cylinder>
            </geometry>
        </collision>
        <collision name='base_footprint_fixed_joint_lump__imu_link_collision_4'>
            <pose>0.4 0 1.377 0 -0 0</pose>
            <geometry>
            <box>
                <size>0.25 0.25 0.25</size>
            </box>
            </geometry>
            <surface>
            <contact>
                <ode/>
            </contact>
            <friction>
                <ode/>
            </friction>
            </surface>
        </collision>
        <collision name='base_footprint_fixed_joint_lump__second_shaft_horizontal_shaft_link_collision_5'>
            <pose>1.552 0 0.536 -1.5708 1.5708 0</pose>
            <geometry>
            <cylinder>
                <length>2.548</length>
                <radius>0.0536</radius>
            </cylinder>
            </geometry>
        </collision>
        <collision name='base_footprint_fixed_joint_lump__second_wheel_left_link_collision_6'>
            <pose>1.552 1.299 0.536 1.5708 -0 3.1408</pose>
            <geometry>
            <cylinder>
                <length>0.385</length>
                <radius>0.536</radius>
            </cylinder>
            </geometry>
        </collision>
        <collision name='base_footprint_fixed_joint_lump__second_wheel_right_link_collision_7'>
            <pose>1.552 -1.299 0.536 1.5708 -0 3.1408</pose>
            <geometry>
            <cylinder>
                <length>0.385</length>
                <radius>0.536</radius>
            </cylinder>
            </geometry>
        </collision>
        <collision name='base_footprint_fixed_joint_lump__third_shaft_horizontal_shaft_link_collision_8'>
            <pose>-2.152 0 0.536 -1.5708 1.5708 0</pose>
            <geometry>
            <cylinder>
                <length>2.548</length>
                <radius>0.0536</radius>
            </cylinder>
            </geometry>
        </collision>
        <collision name='base_footprint_fixed_joint_lump__third_wheel_left_link_collision_9'>
            <pose>-2.152 1.299 0.536 1.5708 -0 3.1408</pose>
            <geometry>
            <cylinder>
                <length>0.385</length>
                <radius>0.536</radius>
            </cylinder>
            </geometry>
        </collision>
        <collision name='base_footprint_fixed_joint_lump__third_wheel_right_link_collision_10'>
            <pose>-2.152 -1.299 0.536 1.5708 -0 3.1408</pose>
            <geometry>
            <cylinder>
                <length>0.385</length>
                <radius>0.536</radius>
            </cylinder>
            </geometry>
        </collision>
        <visual name='base_footprint_fixed_joint_lump__base_link_visual'>
            <pose>0 0 0.877 0 -0 0</pose>
            <geometry>
            <box>
                <size>9.605 2.548 0.877</size>
            </box>
            </geometry>
        </visual>
        <visual name='base_footprint_fixed_joint_lump__cabin_link_visual_1'>
            <pose>3.8205 0 2.095 0 -0 0</pose>
            <geometry>
            <box>
                <size>1.964 2.14 1.833</size>
            </box>
            </geometry>
        </visual>
        <visual name='base_footprint_fixed_joint_lump__lidar_link_visual_2'>
            <pose>4.7825 0 3.122 0 -0 0</pose>
            <geometry>
            <cylinder>
                <length>0.15</length>
                <radius>0.108</radius>
            </cylinder>
            </geometry>
        </visual>
        <visual name='base_footprint_fixed_joint_lump__first_shaft_horizontal_shaft_link_visual_3'>
            <pose>3.302 0 0.536 -1.5708 1.5708 0</pose>
            <geometry>
            <cylinder>
                <length>2.573</length>
                <radius>0.0536</radius>
            </cylinder>
            </geometry>
        </visual>
        <visual name='base_footprint_fixed_joint_lump__fourth_shaft_horizontal_shaft_link_visual_4'>
            <pose>-3.502 0 0.536 -1.5708 1.5708 0</pose>
            <geometry>
            <cylinder>
                <length>2.573</length>
                <radius>0.0536</radius>
            </cylinder>
            </geometry>
        </visual>
        <visual name='base_footprint_fixed_joint_lump__imu_link_visual_5'>
            <pose>0.4 0 1.377 0 -0 0</pose>
            <geometry>
            <box>
                <size>0.25 0.25 0.25</size>
            </box>
            </geometry>
        </visual>
        <visual name='base_footprint_fixed_joint_lump__second_shaft_horizontal_shaft_link_visual_6'>
            <pose>1.552 0 0.536 -1.5708 1.5708 0</pose>
            <geometry>
            <cylinder>
                <length>2.573</length>
                <radius>0.0536</radius>
            </cylinder>
            </geometry>
        </visual>
        <visual name='base_footprint_fixed_joint_lump__second_wheel_left_link_visual_7'>
            <pose>1.552 1.299 0.536 1.5708 -0 3.1408</pose>
            <geometry>
            <cylinder>
                <length>0.385</length>
                <radius>0.536</radius>
            </cylinder>
            </geometry>
        </visual>
        <visual name='base_footprint_fixed_joint_lump__second_wheel_right_link_visual_8'>
            <pose>1.552 -1.299 0.536 1.5708 -0 3.1408</pose>
            <geometry>
            <cylinder>
                <length>0.385</length>
                <radius>0.536</radius>
            </cylinder>
            </geometry>
        </visual>
        <visual name='base_footprint_fixed_joint_lump__third_shaft_horizontal_shaft_link_visual_9'>
            <pose>-2.152 0 0.536 -1.5708 1.5708 0</pose>
            <geometry>
            <cylinder>
                <length>2.573</length>
                <radius>0.0536</radius>
            </cylinder>
            </geometry>
        </visual>
        <visual name='base_footprint_fixed_joint_lump__third_wheel_left_link_visual_10'>
            <pose>-2.152 1.299 0.536 1.5708 -0 3.1408</pose>
            <geometry>
            <cylinder>
                <length>0.385</length>
                <radius>0.536</radius>
            </cylinder>
            </geometry>
        </visual>
        <visual name='base_footprint_fixed_joint_lump__third_wheel_right_link_visual_11'>
            <pose>-2.152 -1.299 0.536 1.5708 -0 3.1408</pose>
            <geometry>
            <cylinder>
                <length>0.385</length>
                <radius>0.536</radius>
            </cylinder>
            </geometry>
        </visual>
        <sensor name='lidar' type='ray'>
            <always_on>1</always_on>
            <visualize>1</visualize>
            <update_rate>5</update_rate>
            <ray>
            <scan>
                <horizontal>
                <samples>360</samples>
                <resolution>1</resolution>
                <min_angle>0</min_angle>
                <max_angle>6.28</max_angle>
                </horizontal>
            </scan>
            <range>
                <min>0.12</min>
                <max>100.0</max>
                <resolution>0.015</resolution>
            </range>
            <noise>
                <type>gaussian</type>
                <mean>0</mean>
                <stddev>0.01</stddev>
            </noise>
            </ray>
            <plugin name='scan' filename='libgazebo_ros_ray_sensor.so'>
            <ros>
                <remapping>~/out:=scan</remapping>
            </ros>
            <output_type>sensor_msgs/LaserScan</output_type>
            <frame_name>lidar_link</frame_name>
            </plugin>
            <pose>4.7825 0 3.122 0 -0 0</pose>
        </sensor>
        <sensor name='imu_sensor' type='imu'>
            <plugin name='imu_plugin' filename='libgazebo_ros_imu_sensor.so'>
            <ros>
                <remapping>~/out:=imu</remapping>
            </ros>
            <initial_orientation_as_reference>0</initial_orientation_as_reference>
            </plugin>
            <always_on>1</always_on>
            <update_rate>200</update_rate>
            <visualize>1</visualize>
            <imu>
            <angular_velocity>
                <x>
                <noise type='gaussian'>
                    <mean>0</mean>
                    <stddev>0.0002</stddev>
                    <bias_mean>7.5e-06</bias_mean>
                    <bias_stddev>8e-07</bias_stddev>
                </noise>
                </x>
                <y>
                <noise type='gaussian'>
                    <mean>0</mean>
                    <stddev>0.0002</stddev>
                    <bias_mean>7.5e-06</bias_mean>
                    <bias_stddev>8e-07</bias_stddev>
                </noise>
                </y>
                <z>
                <noise type='gaussian'>
                    <mean>0</mean>
                    <stddev>0.0002</stddev>
                    <bias_mean>7.5e-06</bias_mean>
                    <bias_stddev>8e-07</bias_stddev>
                </noise>
                </z>
            </angular_velocity>
            <linear_acceleration>
                <x>
                <noise type='gaussian'>
                    <mean>0</mean>
                    <stddev>0.017</stddev>
                    <bias_mean>0.1</bias_mean>
                    <bias_stddev>0.001</bias_stddev>
                </noise>
                </x>
                <y>
                <noise type='gaussian'>
                    <mean>0</mean>
                    <stddev>0.017</stddev>
                    <bias_mean>0.1</bias_mean>
                    <bias_stddev>0.001</bias_stddev>
                </noise>
                </y>
                <z>
                <noise type='gaussian'>
                    <mean>0</mean>
                    <stddev>0.017</stddev>
                    <bias_mean>0.1</bias_mean>
                    <bias_stddev>0.001</bias_stddev>
                </noise>
                </z>
            </linear_acceleration>
            </imu>
            <pose>0.4 0 1.377 0 -0 0</pose>
        </sensor>
        </link>
        <joint name='front_left_steer_joint' type='revolute'>
        <pose relative_to='base_footprint'>3.302 1.299 0.535 0 -0 1.5708</pose>
        <parent>base_footprint</parent>
        <child>front_left_steering_link</child>
        <axis>
            <xyz>0 0 1</xyz>
            <limit>
            <lower>-0.524</lower>
            <upper>0.524</upper>
            <effort>1e+07</effort>
            <velocity>1e+06</velocity>
            </limit>
            <dynamics>
            <spring_reference>0</spring_reference>
            <spring_stiffness>0</spring_stiffness>
            </dynamics>
        </axis>
        </joint>
        <link name='front_left_steering_link'>
        <pose relative_to='front_left_steer_joint'>0 0 0 0 -0 0</pose>
        <inertial>
            <pose>0 0 0 0 -0 0</pose>
            <mass>2</mass>
            <inertia>
            <ixx>0.0729167</ixx>
            <ixy>0</ixy>
            <ixz>0</ixz>
            <iyy>0.0729167</iyy>
            <iyz>0</iyz>
            <izz>0.0625</izz>
            </inertia>
        </inertial>
        <collision name='front_left_steering_link_collision'>
            <pose>0 0 0 0 -0 0</pose>
            <geometry>
            <cylinder>
                <length>0.5</length>
                <radius>0.25</radius>
            </cylinder>
            </geometry>
        </collision>
        <visual name='front_left_steering_link_visual'>
            <pose>0 0 0 0 -0 0</pose>
            <geometry>
            <cylinder>
                <length>0.5</length>
                <radius>0.25</radius>
            </cylinder>
            </geometry>
        </visual>
        </link>
        <joint name='first_wheel_left_joint' type='revolute'>
        <pose relative_to='front_left_steering_link'>0 0 0 0 -0 1.57</pose>
        <parent>front_left_steering_link</parent>
        <child>first_wheel_left_link</child>
        <axis>
            <xyz>0 -1 0</xyz>
            <limit>
            <lower>-1e+16</lower>
            <upper>1e+16</upper>
            </limit>
            <dynamics>
            <spring_reference>0</spring_reference>
            <spring_stiffness>0</spring_stiffness>
            </dynamics>
        </axis>
        </joint>
        <link name='first_wheel_left_link'>
        <pose relative_to='first_wheel_left_joint'>0 0 0 0 -0 0</pose>
        <inertial>
            <pose>0 0 0 0 -0 0</pose>
            <mass>74</mass>
            <inertia>
            <ixx>0.5</ixx>
            <ixy>0</ixy>
            <ixz>0</ixz>
            <iyy>0.5</iyy>
            <iyz>0</iyz>
            <izz>74</izz>
            </inertia>
        </inertial>
        <collision name='first_wheel_left_link_collision'>
            <pose>0 0 0 1.5708 -0 0</pose>
            <geometry>
            <cylinder>
                <length>0.385</length>
                <radius>0.536</radius>
            </cylinder>
            </geometry>
        </collision>
        <visual name='first_wheel_left_link_visual'>
            <pose>0 0 0 1.5708 -0 0</pose>
            <geometry>
            <cylinder>
                <length>0.385</length>
                <radius>0.536</radius>
            </cylinder>
            </geometry>
        </visual>
        </link>
        <joint name='front_right_steer_joint' type='revolute'>
        <pose relative_to='base_footprint'>3.302 -1.299 0.535 0 -0 1.5708</pose>
        <parent>base_footprint</parent>
        <child>front_right_steering_link</child>
        <axis>
            <xyz>0 0 1</xyz>
            <limit>
            <lower>-0.524</lower>
            <upper>0.524</upper>
            <effort>1e+07</effort>
            <velocity>1e+06</velocity>
            </limit>
            <dynamics>
            <spring_reference>0</spring_reference>
            <spring_stiffness>0</spring_stiffness>
            </dynamics>
        </axis>
        </joint>
        <link name='front_right_steering_link'>
        <pose relative_to='front_right_steer_joint'>0 0 0 0 -0 0</pose>
        <inertial>
            <pose>0 0 0 0 -0 0</pose>
            <mass>2</mass>
            <inertia>
            <ixx>0.0729167</ixx>
            <ixy>0</ixy>
            <ixz>0</ixz>
            <iyy>0.0729167</iyy>
            <iyz>0</iyz>
            <izz>0.0625</izz>
            </inertia>
        </inertial>
        <collision name='front_right_steering_link_collision'>
            <pose>0 0 0 0 -0 0</pose>
            <geometry>
            <cylinder>
                <length>0.5</length>
                <radius>0.25</radius>
            </cylinder>
            </geometry>
        </collision>
        <visual name='front_right_steering_link_visual'>
            <pose>0 0 0 0 -0 0</pose>
            <geometry>
            <cylinder>
                <length>0.5</length>
                <radius>0.25</radius>
            </cylinder>
            </geometry>
        </visual>
        </link>
        <joint name='first_wheel_right_joint' type='revolute'>
        <pose relative_to='front_right_steering_link'>0 0 0 0 -0 1.57</pose>
        <parent>front_right_steering_link</parent>
        <child>first_wheel_right_link</child>
        <axis>
            <xyz>0 -1 0</xyz>
            <limit>
            <lower>-1e+16</lower>
            <upper>1e+16</upper>
            </limit>
            <dynamics>
            <spring_reference>0</spring_reference>
            <spring_stiffness>0</spring_stiffness>
            </dynamics>
        </axis>
        </joint>
        <link name='first_wheel_right_link'>
        <pose relative_to='first_wheel_right_joint'>0 0 0 0 -0 0</pose>
        <inertial>
            <pose>0 0 0 0 -0 0</pose>
            <mass>74</mass>
            <inertia>
            <ixx>0.5</ixx>
            <ixy>0</ixy>
            <ixz>0</ixz>
            <iyy>0.5</iyy>
            <iyz>0</iyz>
            <izz>74</izz>
            </inertia>
        </inertial>
        <collision name='first_wheel_right_link_collision'>
            <pose>0 0 0 1.5708 -0 0</pose>
            <geometry>
            <cylinder>
                <length>0.385</length>
                <radius>0.536</radius>
            </cylinder>
            </geometry>
        </collision>
        <visual name='first_wheel_right_link_visual'>
            <pose>0 0 0 1.5708 -0 0</pose>
            <geometry>
            <cylinder>
                <length>0.385</length>
                <radius>0.536</radius>
            </cylinder>
            </geometry>
        </visual>
        </link>
        <joint name='fourth_wheel_left_joint' type='revolute'>
        <pose relative_to='base_footprint'>-3.502 1.299 0.536 0 -0 3.1408</pose>
        <parent>base_footprint</parent>
        <child>fourth_wheel_left_link</child>
        <axis>
            <xyz>0 -1 0</xyz>
            <limit>
            <lower>-1e+16</lower>
            <upper>1e+16</upper>
            </limit>
            <dynamics>
            <spring_reference>0</spring_reference>
            <spring_stiffness>0</spring_stiffness>
            </dynamics>
        </axis>
        </joint>
        <link name='fourth_wheel_left_link'>
        <pose relative_to='fourth_wheel_left_joint'>0 0 0 0 -0 0</pose>
        <inertial>
            <pose>0 0 0 0 -0 0</pose>
            <mass>74</mass>
            <inertia>
            <ixx>0.5</ixx>
            <ixy>0</ixy>
            <ixz>0</ixz>
            <iyy>0.5</iyy>
            <iyz>0</iyz>
            <izz>74</izz>
            </inertia>
        </inertial>
        <collision name='fourth_wheel_left_link_collision'>
            <pose>0 0 0 1.5708 -0 0</pose>
            <geometry>
            <cylinder>
                <length>0.385</length>
                <radius>0.536</radius>
            </cylinder>
            </geometry>
        </collision>
        <visual name='fourth_wheel_left_link_visual'>
            <pose>0 0 0 1.5708 -0 0</pose>
            <geometry>
            <cylinder>
                <length>0.385</length>
                <radius>0.536</radius>
            </cylinder>
            </geometry>
        </visual>
        </link>
        <joint name='fourth_wheel_right_joint' type='revolute'>
        <pose relative_to='base_footprint'>-3.502 -1.299 0.536 0 -0 3.1408</pose>
        <parent>base_footprint</parent>
        <child>fourth_wheel_right_link</child>
        <axis>
            <xyz>0 -1 0</xyz>
            <limit>
            <lower>-1e+16</lower>
            <upper>1e+16</upper>
            </limit>
            <dynamics>
            <spring_reference>0</spring_reference>
            <spring_stiffness>0</spring_stiffness>
            </dynamics>
        </axis>
        </joint>
        <link name='fourth_wheel_right_link'>
        <pose relative_to='fourth_wheel_right_joint'>0 0 0 0 -0 0</pose>
        <inertial>
            <pose>0 0 0 0 -0 0</pose>
            <mass>74</mass>
            <inertia>
            <ixx>0.5</ixx>
            <ixy>0</ixy>
            <ixz>0</ixz>
            <iyy>0.5</iyy>
            <iyz>0</iyz>
            <izz>74</izz>
            </inertia>
        </inertial>
        <collision name='fourth_wheel_right_link_collision'>
            <pose>0 0 0 1.5708 -0 0</pose>
            <geometry>
            <cylinder>
                <length>0.385</length>
                <radius>0.536</radius>
            </cylinder>
            </geometry>
        </collision>
        <visual name='fourth_wheel_right_link_visual'>
            <pose>0 0 0 1.5708 -0 0</pose>
            <geometry>
            <cylinder>
                <length>0.385</length>
                <radius>0.536</radius>
            </cylinder>
            </geometry>
        </visual>
        </link>
        <plugin name='ackermann_drive' filename='libgazebo_ros_ackermann_drive.so'>
        <ros>
            <parameter name='cmd_vel_topic' value='cmd_vel'/>
            <parameter name='odom_topic' value='odom'/>
            <parameter name='distance_topic' value='distance'/>
        </ros>
        <update_rate>1.0</update_rate>
        <front_left_joint>first_wheel_left_joint</front_left_joint>
        <front_right_joint>first_wheel_right_joint</front_right_joint>
        <rear_left_joint>fourth_wheel_left_joint</rear_left_joint>
        <rear_right_joint>fourth_wheel_right_joint</rear_right_joint>
        <left_steering_joint>front_left_steer_joint</left_steering_joint>
        <right_steering_joint>front_right_steer_joint</right_steering_joint>
        <max_steer>0.6458</max_steer>
        <max_steering_angle>7.85</max_steering_angle>
        <max_speed>20</max_speed>
        <left_steering_pid_gain>1500 0 1</left_steering_pid_gain>
        <left_steering_i_range>0 0</left_steering_i_range>
        <right_steering_pid_gain>1500 0 1</right_steering_pid_gain>
        <right_steering_i_range>0 0</right_steering_i_range>
        <linear_velocity_pid_gain>1000 0 1</linear_velocity_pid_gain>
        <linear_velocity_i_range>0 0</linear_velocity_i_range>
        <publish_odom>1</publish_odom>
        <publish_odom_tf>1</publish_odom_tf>
        <publish_wheel_tf>1</publish_wheel_tf>
        <publish_distance>1</publish_distance>
        <odometry_frame>odom</odometry_frame>
        <robot_base_frame>base_footprint</robot_base_frame>
        </plugin>
        <plugin name='truck_joint_state' filename='libgazebo_ros_joint_state_publisher.so'>
        <ros>
            <remapping>~/out:=joint_states</remapping>
        </ros>
        <update_rate>30</update_rate>
        <joint_name>front_right_steer_joint</joint_name>
        <joint_name>front_left_steer_joint</joint_name>
        <joint_name>first_wheel_left_joint</joint_name>
        <joint_name>first_wheel_right_joint</joint_name>
        <joint_name>fourth_wheel_left_joint</joint_name>
        <joint_name>fourth_wheel_right_joint</joint_name>
        </plugin>
        <frame name='lidar_to_support_link' attached_to='cabin_link'>
        <pose>0.962 0 1.027 0 -0 0</pose>
        </frame>
        <frame name='lidar_link' attached_to='lidar_to_support_link'/>
        <frame name='cabin_joint' attached_to='base_link'>
        <pose>3.8205 0 1.218 0 -0 0</pose>
        </frame>
        <frame name='cabin_link' attached_to='cabin_joint'/>
        <frame name='first_shaft_horizontal_shaft_joint' attached_to='base_link'>
        <pose>3.302 0 -0.341 0 -0 1.5708</pose>
        </frame>
        <frame name='first_shaft_horizontal_shaft_link' attached_to='first_shaft_horizontal_shaft_joint'/>
        <frame name='fourth_shaft_horizontal_shaft_joint' attached_to='base_link'>
        <pose>-3.502 0 -0.341 0 -0 1.5708</pose>
        </frame>
        <frame name='fourth_shaft_horizontal_shaft_link' attached_to='fourth_shaft_horizontal_shaft_joint'/>
        <frame name='imu_joint' attached_to='base_link'>
        <pose>0.4 0 0.5 0 -0 0</pose>
        </frame>
        <frame name='imu_link' attached_to='imu_joint'/>
        <frame name='second_wheel_left_joint' attached_to='second_shaft_horizontal_shaft_link'>
        <pose>1.299 0 0 0 -0 1.57</pose>
        </frame>
        <frame name='second_wheel_left_link' attached_to='second_wheel_left_joint'/>
        <frame name='second_wheel_right_joint' attached_to='second_shaft_horizontal_shaft_link'>
        <pose>-1.299 0 0 0 -0 1.57</pose>
        </frame>
        <frame name='second_wheel_right_link' attached_to='second_wheel_right_joint'/>
        <frame name='second_shaft_horizontal_shaft_joint' attached_to='base_link'>
        <pose>1.552 0 -0.341 0 -0 1.5708</pose>
        </frame>
        <frame name='second_shaft_horizontal_shaft_link' attached_to='second_shaft_horizontal_shaft_joint'/>
        <frame name='third_wheel_left_joint' attached_to='third_shaft_horizontal_shaft_link'>
        <pose>1.299 0 0 0 -0 1.57</pose>
        </frame>
        <frame name='third_wheel_left_link' attached_to='third_wheel_left_joint'/>
        <frame name='third_wheel_right_joint' attached_to='third_shaft_horizontal_shaft_link'>
        <pose>-1.299 0 0 0 -0 1.57</pose>
        </frame>
        <frame name='third_wheel_right_link' attached_to='third_wheel_right_joint'/>
        <frame name='third_shaft_horizontal_shaft_joint' attached_to='base_link'>
        <pose>-2.152 0 -0.341 0 -0 1.5708</pose>
        </frame>
        <frame name='third_shaft_horizontal_shaft_link' attached_to='third_shaft_horizontal_shaft_joint'/>
        <frame name='base_joint' attached_to='base_footprint'>
        <pose>0 0 0.877 0 -0 0</pose>
        </frame>
        <frame name='base_link' attached_to='base_joint'/>
    </model>
  </world>
</sdf>
