<?xml version="1.0" ?>
<!-- =================================================================================== -->
<!-- |    This document was autogenerated by xacro from ackerman.xacro                 | -->
<!-- |    EDITING THIS FILE BY HAND IS NOT RECOMMENDED                                 | -->
<!-- =================================================================================== -->
<robot name="ackermann_robot">
  <!-- Calculado na mão-->
  <!-- Material Definitions -->
  <!-- Init colour -->
  <material name="black">
    <color rgba="0.0 0.0 0.0 1.0"/>
  </material>
  <material name="dark">
    <color rgba="0.3 0.3 0.3 1.0"/>
  </material>
  <material name="light_black">
    <color rgba="0.4 0.4 0.4 1.0"/>
  </material>
  <material name="blue">
    <color rgba="0.0 0.0 0.8 1.0"/>
  </material>
  <material name="green">
    <color rgba="0.0 0.8 0.0 1.0"/>
  </material>
  <material name="grey">
    <color rgba="0.5 0.5 0.5 1.0"/>
  </material>
  <material name="orange">
    <color rgba="1.0 0.4235 0.0392 1.0"/>
  </material>
  <material name="brown">
    <color rgba="0.8706 0.8118 0.7647 1.0"/>
  </material>
  <material name="red">
    <color rgba="0.8 0.0 0.0 1.0"/>
  </material>
  <material name="white">
    <color rgba="1.0 1.0 1.0 1.0"/>
  </material>
  <!--Robot Footprint -->
  <!-- <link name="base_footprint"/> -->
  <!--Robot Footprint Visualization-->
  <link name="base_footprint">
    <visual>
      <origin rpy="0 0 0" xyz="0 0 0"/>
      <geometry>
        <box size="1.0 0.4 0.001"/>
      </geometry>
      <material name="red"/>
    </visual>
  </link>
  <!-- Base Link -->
  <link name="base_link">
    <visual>
      <geometry>
        <box size="1.0 0.4 0.05"/>
      </geometry>
      <material name="Cyan">
        <color rgba="0 1.0 1.0 1.0"/>
      </material>
    </visual>
    <collision>
      <geometry>
        <box size="1.0 0.4 0.05"/>
      </geometry>
    </collision>
    <inertial>
      <origin rpy="1.5707963267948966 0 1.5707963267948966" xyz="0 0 0"/>
      <mass value="10"/>
      <inertia ixx="0.8354166666666667" ixy="0.0" ixz="0.0" iyy="0.9666666666666668" iyz="0.0" izz="0.1354166666666667"/>
    </inertial>
  </link>
  <joint name="base_joint" type="fixed">
    <origin rpy="0 0 0" xyz="0 0 0.1"/>
    <parent link="base_footprint"/>
    <child link="base_link"/>
  </joint>
  <link name="rear_horizontal_shaft_link">
    <visual>
      <geometry>
        <cylinder length="0.7" radius="0.025"/>
      </geometry>
      <material name="orange">
        <color rgba="0 0 0 1.0"/>
      </material>
      <origin rpy="0 1.5707963267948966 0" xyz="0 0 0"/>
    </visual>
    <collision>
      <geometry>
        <cylinder length="0.7" radius="0.025"/>
      </geometry>
      <origin rpy="0 1.5707963267948966 0" xyz="0 0 0"/>
    </collision>
    <inertial>
      <origin rpy="0 0 0" xyz="0 0 0"/>
      <mass value="1"/>
      <inertia ixx="0.04098958333333333" ixy="0.0" ixz="0.0" iyy="0.04098958333333333" iyz="0.0" izz="0.00031250000000000006"/>
    </inertial>
  </link>
  <link name="frontal_horizontal_shaft_link">
    <visual>
      <geometry>
        <cylinder length="0.7" radius="0.025"/>
      </geometry>
      <material name="orange">
        <color rgba="0 0 0 1.0"/>
      </material>
      <origin rpy="0 1.5707963267948966 0" xyz="0 0 0"/>
    </visual>
    <collision>
      <geometry>
        <cylinder length="0.7" radius="0.025"/>
      </geometry>
      <origin rpy="0 1.5707963267948966 0" xyz="0 0 0"/>
    </collision>
    <inertial>
      <origin rpy="0 0 0" xyz="0 0 0"/>
      <mass value="1"/>
      <inertia ixx="0.04098958333333333" ixy="0.0" ixz="0.0" iyy="0.04098958333333333" iyz="0.0" izz="0.00031250000000000006"/>
    </inertial>
  </link>
  <joint name="rear_horizontal_shaft_joint" type="fixed">
    <parent link="base_link"/>
    <child link="rear_horizontal_shaft_link"/>
    <origin rpy="0 0 1.5707963267948966" xyz="-0.35 0 0"/>
    <axis xyz="0 0 1"/>
    <!-- <limit lower="-0.131" upper="0.131" effort="10000000" velocity="1000000"/> -->
    <!-- Just if change to revolute joint-->
  </joint>
  <joint name="frontal_horizontal_shaft_joint" type="fixed">
    <parent link="base_link"/>
    <child link="frontal_horizontal_shaft_link"/>
    <origin rpy="0 0 1.5707963267948966" xyz="0.35 0 0"/>
    <axis xyz="0 0 1"/>
    <!-- <limit lower="-0.131" upper="0.131" effort="10000000" velocity="1000000"/> -->
    <!-- Just if change to revolute joint-->
  </joint>
  <link name="front_right_steering_link">
    <visual>
      <geometry>
        <cylinder length="0.01" radius="0.05"/>
      </geometry>
      <material name="white"/>
    </visual>
    <collision>
      <geometry>
        <cylinder length="0.01" radius="0.05"/>
      </geometry>
    </collision>
    <inertial>
      <origin rpy="0 0 0" xyz="0 0 0"/>
      <mass value="0.5"/>
      <inertia ixx="0.0003166666666666667" ixy="0.0" ixz="0.0" iyy="0.0003166666666666667" iyz="0.0" izz="0.0006250000000000001"/>
    </inertial>
  </link>
  <link name="front_left_steering_link">
    <visual>
      <geometry>
        <cylinder length="0.01" radius="0.05"/>
      </geometry>
      <material name="white"/>
    </visual>
    <collision>
      <geometry>
        <cylinder length="0.01" radius="0.05"/>
      </geometry>
    </collision>
    <inertial>
      <origin rpy="0 0 0" xyz="0 0 0"/>
      <mass value="0.5"/>
      <inertia ixx="0.0003166666666666667" ixy="0.0" ixz="0.0" iyy="0.0003166666666666667" iyz="0.0" izz="0.0006250000000000001"/>
    </inertial>
  </link>
  <joint name="front_right_steer_joint" type="revolute">
    <parent link="frontal_horizontal_shaft_link"/>
    <child link="front_right_steering_link"/>
    <origin rpy="0 1.57 0" xyz="0.3 0 -0.001"/>
    <axis xyz="1 0 0"/>
    <limit effort="10000000" lower="-0.524" upper="0.524" velocity="1000000"/>
  </joint>
  <joint name="front_left_steer_joint" type="revolute">
    <parent link="frontal_horizontal_shaft_link"/>
    <child link="front_left_steering_link"/>
    <origin rpy="0 1.57 0" xyz="-0.3 0 -0.001"/>
    <axis xyz="1 0 0"/>
    <limit effort="10000000" lower="-0.524" upper="0.524" velocity="1000000"/>
  </joint>
  <!-- WHEELS-->
  <!-- Xacro macro for the wheel -->
  <link name="rear_wheel_left_link">
    <visual>
      <origin rpy="0 0 0" xyz="0 0 0"/>
      <geometry>
        <cylinder length="0.1" radius="0.1"/>
      </geometry>
      <material name="brown"/>
    </visual>
    <inertial>
      <origin rpy="0 0 0" xyz="0 0 0"/>
      <mass value="1"/>
      <inertia ixx="0.5 * 1 * 0.1 * 0.1" ixy="0" ixz="0" iyy="0.5 * 1 * 0.1 * 0.1" iyz="0" izz="1 * 0.1 * 0.1"/>
    </inertial>
    <collision>
      <geometry>
        <cylinder length="0.1" radius="0.1"/>
      </geometry>
      <origin rpy="0 0 0" xyz="0 0 0"/>
    </collision>
  </link>
  <joint name="rear_wheel_left_rear_joint" type="continuous">
    <parent link="rear_horizontal_shaft_link"/>
    <child link="rear_wheel_left_link"/>
    <origin rpy="0 1.57 0" xyz="0.3 0 0"/>
    <axis xyz="0 0 1"/>
  </joint>
  <link name="rear_wheel_right_link">
    <visual>
      <origin rpy="0 0 0" xyz="0 0 0"/>
      <geometry>
        <cylinder length="0.1" radius="0.1"/>
      </geometry>
      <material name="brown"/>
    </visual>
    <inertial>
      <origin rpy="0 0 0" xyz="0 0 0"/>
      <mass value="1"/>
      <inertia ixx="0.5 * 1 * 0.1 * 0.1" ixy="0" ixz="0" iyy="0.5 * 1 * 0.1 * 0.1" iyz="0" izz="1 * 0.1 * 0.1"/>
    </inertial>
    <collision>
      <geometry>
        <cylinder length="0.1" radius="0.1"/>
      </geometry>
      <origin rpy="0 0 0" xyz="0 0 0"/>
    </collision>
  </link>
  <joint name="rear_wheel_right_rear_joint" type="continuous">
    <parent link="rear_horizontal_shaft_link"/>
    <child link="rear_wheel_right_link"/>
    <origin rpy="0 1.57 0" xyz="-0.3 0 0"/>
    <axis xyz="0 0 1"/>
  </joint>
  <link name="frontal_wheel_left_link">
    <visual>
      <origin rpy="0 0 0" xyz="0 0 0"/>
      <geometry>
        <cylinder length="0.1" radius="0.1"/>
      </geometry>
      <material name="brown"/>
    </visual>
    <inertial>
      <origin rpy="0 0 0" xyz="0 0 0"/>
      <mass value="1"/>
      <inertia ixx="0.5 * 1 * 0.1 * 0.1" ixy="0" ixz="0" iyy="0.5 * 1 * 0.1 * 0.1" iyz="0" izz="1 * 0.1 * 0.1"/>
    </inertial>
    <collision>
      <geometry>
        <cylinder length="0.1" radius="0.1"/>
      </geometry>
      <origin rpy="0 0 0" xyz="0 0 0"/>
    </collision>
  </link>
  <joint name="frontal_wheel_left_frontal_joint" type="continuous">
    <parent link="front_left_steering_link"/>
    <child link="frontal_wheel_left_link"/>
    <origin rpy="0 0 1.57" xyz="0 0 0"/>
    <axis xyz="0 0 1"/>
  </joint>
  <link name="frontal_wheel_right_link">
    <visual>
      <origin rpy="0 0 0" xyz="0 0 0"/>
      <geometry>
        <cylinder length="0.1" radius="0.1"/>
      </geometry>
      <material name="brown"/>
    </visual>
    <inertial>
      <origin rpy="0 0 0" xyz="0 0 0"/>
      <mass value="1"/>
      <inertia ixx="0.5 * 1 * 0.1 * 0.1" ixy="0" ixz="0" iyy="0.5 * 1 * 0.1 * 0.1" iyz="0" izz="1 * 0.1 * 0.1"/>
    </inertial>
    <collision>
      <geometry>
        <cylinder length="0.1" radius="0.1"/>
      </geometry>
      <origin rpy="0 0 0" xyz="0 0 0"/>
    </collision>
  </link>
  <joint name="frontal_wheel_right_frontal_joint" type="continuous">
    <parent link="front_right_steering_link"/>
    <child link="frontal_wheel_right_link"/>
    <origin rpy="0 0 1.57" xyz="0 0 0"/>
    <axis xyz="0 0 1"/>
  </joint>
  <!-- Steering Wheel to fit Ackerman plugin-->
  <!-- Steering Wheel Link -->
  <!-- <link name="steering_wheel">
    <inertial>
      <mass value="1.0"/>
      <inertia ixx="0.14583300" ixy="0.0" ixz="0.0" iyy="0.14583300" iyz="0.0" izz="0.125"/>
    </inertial>
    <visual>
      <origin xyz="0 0 0" rpy="1.302101 0 0"/>
      <geometry>
        <cylinder radius="0.05" length="0.01"/>
      </geometry>
      <material name="blue"/>
    </visual>
    <collision>
      <origin xyz="0 0 0" rpy="1.302101 0 0"/>
      <geometry>
        <cylinder radius="0.05" length="0.01"/>
      </geometry>
    </collision>
  </link> -->
  <!-- Steering Joint -->
  <!-- <joint name="steering_joint" type="continuous">
    <origin xyz="0.4 0 0.2" rpy="0 0 1.57"/> 
    <parent link="base_link"/>
    <child link="steering_wheel"/>
    <axis xyz="0 0 1"/>
    <limit lower="-7.85" upper="7.85" effort="10000000" velocity="1000000"/>
  </joint> -->
  <!--Sensors -->
  <!-- Imu Link-->
  <link name="imu_link">
    <visual>
      <geometry>
        <box size="0.05 0.05 0.05"/>
      </geometry>
      <material name="grey"/>
    </visual>
    <collision>
      <geometry>
        <box size="0.05 0.05 0.05"/>
      </geometry>
    </collision>
    <inertial>
      <origin rpy="1.5707963267948966 0 1.5707963267948966" xyz="0 0 0"/>
      <mass value="0.1"/>
      <inertia ixx="0.0001666666666666667" ixy="0.0" ixz="0.0" iyy="0.0001666666666666667" iyz="0.0" izz="0.0001666666666666667"/>
    </inertial>
  </link>
  <joint name="imu_joint" type="fixed">
    <parent link="base_link"/>
    <child link="imu_link"/>
    <origin xyz="0.4 0 0.05"/>
  </joint>
  <!-- LiDAR support base link -->
  <link name="lidar_base_link">
    <inertial>
      <origin rpy="0 0 0" xyz="0 0 0"/>
      <mass value="0.1"/>
      <inertia ixx="0.001" ixy="0" ixz="0" iyy="0.001" iyz="0" izz="0.001"/>
    </inertial>
    <visual>
      <origin rpy="0 0 0" xyz="0 0 0"/>
      <geometry>
        <box size="0.3 0.2 0.1"/>
      </geometry>
      <visual name="blue"/>
    </visual>
    <collision>
      <origin rpy="0 0 0" xyz="0 0 0"/>
      <geometry>
        <box size="0.1 0.1 0.1"/>
      </geometry>
    </collision>
  </link>
  <!-- Fixed joint between cabin_link and lidar_base_link -->
  <joint name="lidar_base_joint" type="fixed">
    <parent link="base_link"/>
    <child link="lidar_base_link"/>
    <origin rpy="0 0 0" xyz="0.0 0 0.01"/>
  </joint>
  <!-- Position X = -0.99 Z = 1.035    Pitched 20 degrees down = -0.1745033 | 5 degrees =0.0425 -->
  <!-- Lidar-->
  <!--Lidar Link-->
  <link name="lidar_link">
    <inertial>
      <origin rpy="0 0 0" xyz="0 0 0"/>
      <mass value="0.125"/>
      <inertia ixx="0.001" ixy="0" ixz="0" iyy="0.001" iyz="0" izz="0.001"/>
    </inertial>
    <collision>
      <origin rpy="0 0 0" xyz="0 0 0"/>
      <geometry>
        <cylinder length="0.055" radius="0.0508"/>
      </geometry>
    </collision>
    <visual>
      <origin rpy="0 0 0" xyz="0 0 0"/>
      <geometry>
        <cylinder length="0.055" radius="0.0508"/>
      </geometry>
      <material name="red"/>
    </visual>
  </link>
  <joint name="lidar_direct_to_base_link" type="fixed">
    <parent link="lidar_base_link"/>
    <child link="lidar_link"/>
    <origin rpy="0 0 0" xyz="0.0 0.0 0.1"/>
  </joint>
  <!-- Gazebo Plugins -->
  <!-- IMU -->
  <gazebo reference="imu_link">
    <sensor name="imu_sensor" type="imu">
      <plugin filename="libgazebo_ros_imu_sensor.so" name="imu_plugin">
        <ros>
          <!-- <namespace>/demo</namespace> -->
          <remapping>~/out:=imu</remapping>
        </ros>
        <initial_orientation_as_reference>false</initial_orientation_as_reference>
      </plugin>
      <always_on>true</always_on>
      <update_rate>200</update_rate>
      <visualize>true</visualize>
      <imu>
        <angular_velocity>
          <x>
            <noise type="gaussian">
              <mean>0.0</mean>
              <stddev>2e-4</stddev>
              <bias_mean>0.0000075</bias_mean>
              <bias_stddev>0.0000008</bias_stddev>
            </noise>
          </x>
          <y>
            <noise type="gaussian">
              <mean>0.0</mean>
              <stddev>2e-4</stddev>
              <bias_mean>0.0000075</bias_mean>
              <bias_stddev>0.0000008</bias_stddev>
            </noise>
          </y>
          <z>
            <noise type="gaussian">
              <mean>0.0</mean>
              <stddev>2e-4</stddev>
              <bias_mean>0.0000075</bias_mean>
              <bias_stddev>0.0000008</bias_stddev>
            </noise>
          </z>
        </angular_velocity>
        <linear_acceleration>
          <x>
            <noise type="gaussian">
              <mean>0.0</mean>
              <stddev>1.7e-2</stddev>
              <bias_mean>0.1</bias_mean>
              <bias_stddev>0.001</bias_stddev>
            </noise>
          </x>
          <y>
            <noise type="gaussian">
              <mean>0.0</mean>
              <stddev>1.7e-2</stddev>
              <bias_mean>0.1</bias_mean>
              <bias_stddev>0.001</bias_stddev>
            </noise>
          </y>
          <z>
            <noise type="gaussian">
              <mean>0.0</mean>
              <stddev>1.7e-2</stddev>
              <bias_mean>0.1</bias_mean>
              <bias_stddev>0.001</bias_stddev>
            </noise>
          </z>
        </linear_acceleration>
      </imu>
    </sensor>
  </gazebo>
  <!-- LiDAR Sensor -->
  <gazebo reference="lidar_link">
    <sensor name="lidar" type="ray">
      <always_on>true</always_on>
      <visualize>true</visualize>
      <update_rate>5</update_rate>
      <ray>
        <scan>
          <horizontal>
            <samples>360</samples>
            <resolution>1.000000</resolution>
            <min_angle>0.000000</min_angle>
            <max_angle>6.280000</max_angle>
          </horizontal>
        </scan>
        <range>
          <min>0.12</min>
          <!-- Calculated in the same rate of turtlebot example which the min range is = 3.5% of the max range-->
          <max>3.5</max>
          <!-- MAximum range of VLP 16 is 100 meters-->
          <resolution>0.015000</resolution>
        </range>
        <noise>
          <type>gaussian</type>
          <mean>0.0</mean>
          <stddev>0.01</stddev>
        </noise>
      </ray>
      <plugin filename="libgazebo_ros_ray_sensor.so" name="scan">
        <ros>
          <remapping>~/out:=scan</remapping>
        </ros>
        <output_type>sensor_msgs/LaserScan</output_type>
        <frame_name>lidar_link</frame_name>
      </plugin>
    </sensor>
  </gazebo>
  <gazebo>
    <plugin filename="libgazebo_ros_ackermann_drive.so" name="ackermann_drive">
      <ros>
        <!-- <namespace>/demo</namespace> -->
        <parameter name="cmd_vel_topic" value="cmd_vel"/>
        <parameter name="odom_topic" value="odom"/>
        <parameter name="distance_topic" value="distance"/>
      </ros>
      <!-- further reduced the update rate -->
      <update_rate>1.0</update_rate>
      <!-- wheels -->
      <front_left_joint>frontal_wheel_left_frontal_joint</front_left_joint>
      <front_right_joint>frontal_wheel_right_frontal_joint</front_right_joint>
      <rear_left_joint>rear_wheel_left_rear_joint</rear_left_joint>
      <rear_right_joint>rear_wheel_right_rear_joint</rear_right_joint>
      <left_steering_joint>front_right_steer_joint</left_steering_joint>
      <right_steering_joint>front_left_steer_joint</right_steering_joint>
      <!-- further reduced the max steer angle -->
      <max_steer>0.1</max_steer>
      <!-- further reduced the max steering angle -->
      <max_steering_angle>1.0</max_steering_angle>
      <!-- further reduced the max speed -->
      <max_speed>1</max_speed>
      <!-- PID tuning -->
      <!-- Further Reduced the P term of PID -->
      <left_steering_pid_gain>100 0 0.1</left_steering_pid_gain>
      <left_steering_i_range>0 0</left_steering_i_range>
      <right_steering_pid_gain>100 0 0.1</right_steering_pid_gain>
      <right_steering_i_range>0 0</right_steering_i_range>
      <linear_velocity_pid_gain>100 0 0.1</linear_velocity_pid_gain>
      <linear_velocity_i_range>0 0</linear_velocity_i_range>
      <!-- output -->
      <publish_odom>true</publish_odom>
      <publish_odom_tf>true</publish_odom_tf>
      <publish_wheel_tf>true</publish_wheel_tf>
      <publish_distance>true</publish_distance>
      <odometry_frame>odom</odometry_frame>
      <robot_base_frame>base_footprint</robot_base_frame>
    </plugin>
  </gazebo>
  <gazebo>
    <plugin filename="libgazebo_ros_joint_state_publisher.so" name="truck_joint_state">
      <ros>
        <!-- <namespace>/tb3</namespace> -->
        <remapping>~/out:=joint_states</remapping>
      </ros>
      <update_rate>30</update_rate>
      <joint_name>front_right_steer_joint</joint_name>
      <joint_name>front_left_steer_joint</joint_name>
      <joint_name>frontal_wheel_left_frontal_joint</joint_name>
      <joint_name>frontal_wheel_right_frontal_joint</joint_name>
      <joint_name>rear_wheel_left_rear_joint</joint_name>
      <joint_name>rear_wheel_right_rear_joint</joint_name>
    </plugin>
  </gazebo>
</robot>
