<sdf version='1.7'>
  <model name='sam_bot'>
    <link name='base_footprint'>
      <inertial>
        <pose>0.004919 0 0.148271 1.5708 -0 1.5708</pose>
        <mass>15.76</mass>
        <inertia>
          <ixx>0.280824</ixx>
          <ixy>1.64009e-18</ixy>
          <ixz>-3.12639e-18</ixz>
          <iyy>0.354548</iyy>
          <iyz>0.0057897</iyz>
          <izz>0.169412</izz>
        </inertia>
      </inertial>
      <collision name='base_footprint_fixed_joint_lump__base_link_collision'>
        <pose>0 0 0.15 0 -0 0</pose>
        <geometry>
          <box>
            <size>0.42 0.31 0.18</size>
          </box>
        </geometry>
      </collision>
      <collision name='base_footprint_fixed_joint_lump__camera_link_collision_1'>
        <pose>0.215 0 0.2 0 -0 0</pose>
        <geometry>
          <box>
            <size>0.015 0.13 0.022</size>
          </box>
        </geometry>
        <surface>
          <contact>
            <ode/>
          </contact>
          <friction>
            <ode/>
          </friction>
        </surface>
      </collision>
      <collision name='base_footprint_fixed_joint_lump__front_caster_collision_2'>
        <pose>0.14 0 0.06 0 -0 0</pose>
        <geometry>
          <sphere>
            <radius>0.06</radius>
          </sphere>
        </geometry>
      </collision>
      <collision name='base_footprint_fixed_joint_lump__imu_link_collision_3'>
        <pose>0 0 0.16 0 -0 0</pose>
        <geometry>
          <box>
            <size>0.1 0.1 0.1</size>
          </box>
        </geometry>
        <surface>
          <contact>
            <ode/>
          </contact>
          <friction>
            <ode/>
          </friction>
        </surface>
      </collision>
      <collision name='base_footprint_fixed_joint_lump__lidar_link_collision_4'>
        <pose>0 0 0.27 0 -0 0</pose>
        <geometry>
          <cylinder>
            <length>0.055</length>
            <radius>0.0508</radius>
          </cylinder>
        </geometry>
        <surface>
          <contact>
            <ode/>
          </contact>
          <friction>
            <ode/>
          </friction>
        </surface>
      </collision>
      <visual name='base_footprint_fixed_joint_lump__base_link_visual'>
        <pose>0 0 0.15 0 -0 0</pose>
        <geometry>
          <box>
            <size>0.42 0.31 0.18</size>
          </box>
        </geometry>
      </visual>
      <visual name='base_footprint_fixed_joint_lump__camera_link_visual_1'>
        <pose>0.215 0 0.2 0 -0 0</pose>
        <geometry>
          <box>
            <size>0.015 0.13 0.022</size>
          </box>
        </geometry>
      </visual>
      <visual name='base_footprint_fixed_joint_lump__front_caster_visual_2'>
        <pose>0.14 0 0.06 0 -0 0</pose>
        <geometry>
          <sphere>
            <radius>0.06</radius>
          </sphere>
        </geometry>
      </visual>
      <visual name='base_footprint_fixed_joint_lump__imu_link_visual_3'>
        <pose>0 0 0.16 0 -0 0</pose>
        <geometry>
          <box>
            <size>0.1 0.1 0.1</size>
          </box>
        </geometry>
      </visual>
      <visual name='base_footprint_fixed_joint_lump__lidar_link_visual_4'>
        <pose>0 0 0.27 0 -0 0</pose>
        <geometry>
          <cylinder>
            <length>0.055</length>
            <radius>0.0508</radius>
          </cylinder>
        </geometry>
      </visual>
      <sensor name='depth_camera' type='depth'>
        <visualize>1</visualize>
        <update_rate>30</update_rate>
        <camera name='camera'>
          <horizontal_fov>1.0472</horizontal_fov>
          <image>
            <width>640</width>
            <height>480</height>
            <format>R8G8B8</format>
          </image>
          <clip>
            <near>0.05</near>
            <far>3</far>
          </clip>
        </camera>
        <plugin name='depth_camera_controller' filename='libgazebo_ros_camera.so'>
          <baseline>0.2</baseline>
          <alwaysOn>1</alwaysOn>
          <updateRate>0.0</updateRate>
          <frame_name>camera_depth_frame</frame_name>
          <pointCloudCutoff>0.5</pointCloudCutoff>
          <pointCloudCutoffMax>3.0</pointCloudCutoffMax>
          <distortionK1>0</distortionK1>
          <distortionK2>0</distortionK2>
          <distortionK3>0</distortionK3>
          <distortionT1>0</distortionT1>
          <distortionT2>0</distortionT2>
          <CxPrime>0</CxPrime>
          <Cx>0</Cx>
          <Cy>0</Cy>
          <focalLength>0</focalLength>
          <hackBaseline>0</hackBaseline>
        </plugin>
        <pose>0.215 0 0.2 0 -0 0</pose>
      </sensor>
      <sensor name='imu_sensor' type='imu'>
        <plugin name='imu_plugin' filename='libgazebo_ros_imu_sensor.so'>
          <ros>
            <remapping>~/out:=imu</remapping>
          </ros>
          <initial_orientation_as_reference>0</initial_orientation_as_reference>
        </plugin>
        <always_on>1</always_on>
        <update_rate>100</update_rate>
        <visualize>1</visualize>
        <imu>
          <angular_velocity>
            <x>
              <noise type='gaussian'>
                <mean>0</mean>
                <stddev>0.0002</stddev>
                <bias_mean>7.5e-06</bias_mean>
                <bias_stddev>8e-07</bias_stddev>
              </noise>
            </x>
            <y>
              <noise type='gaussian'>
                <mean>0</mean>
                <stddev>0.0002</stddev>
                <bias_mean>7.5e-06</bias_mean>
                <bias_stddev>8e-07</bias_stddev>
              </noise>
            </y>
            <z>
              <noise type='gaussian'>
                <mean>0</mean>
                <stddev>0.0002</stddev>
                <bias_mean>7.5e-06</bias_mean>
                <bias_stddev>8e-07</bias_stddev>
              </noise>
            </z>
          </angular_velocity>
          <linear_acceleration>
            <x>
              <noise type='gaussian'>
                <mean>0</mean>
                <stddev>0.017</stddev>
                <bias_mean>0.1</bias_mean>
                <bias_stddev>0.001</bias_stddev>
              </noise>
            </x>
            <y>
              <noise type='gaussian'>
                <mean>0</mean>
                <stddev>0.017</stddev>
                <bias_mean>0.1</bias_mean>
                <bias_stddev>0.001</bias_stddev>
              </noise>
            </y>
            <z>
              <noise type='gaussian'>
                <mean>0</mean>
                <stddev>0.017</stddev>
                <bias_mean>0.1</bias_mean>
                <bias_stddev>0.001</bias_stddev>
              </noise>
            </z>
          </linear_acceleration>
        </imu>
        <pose>0 0 0.16 0 -0 0</pose>
      </sensor>
      <sensor name='lidar' type='ray'>
        <always_on>1</always_on>
        <visualize>1</visualize>
        <update_rate>5</update_rate>
        <ray>
          <scan>
            <horizontal>
              <samples>360</samples>
              <resolution>1</resolution>
              <min_angle>0</min_angle>
              <max_angle>6.28</max_angle>
            </horizontal>
          </scan>
          <range>
            <min>0.12</min>
            <max>3.5</max>
            <resolution>0.015</resolution>
          </range>
          <noise>
            <type>gaussian</type>
            <mean>0</mean>
            <stddev>0.01</stddev>
          </noise>
        </ray>
        <plugin name='scan' filename='libgazebo_ros_ray_sensor.so'>
          <ros>
            <remapping>~/out:=scan</remapping>
          </ros>
          <output_type>sensor_msgs/LaserScan</output_type>
          <frame_name>lidar_link</frame_name>
        </plugin>
        <pose>0 0 0.27 0 -0 0</pose>
      </sensor>
    </link>
    <joint name='drivewhl_l_joint' type='revolute'>
      <pose relative_to='base_footprint'>-0.12 0.18 0.1 0 -0 0</pose>
      <parent>base_footprint</parent>
      <child>drivewhl_l_link</child>
      <axis>
        <xyz>0 1 0</xyz>
        <limit>
          <lower>-1e+16</lower>
          <upper>1e+16</upper>
        </limit>
        <dynamics>
          <spring_reference>0</spring_reference>
          <spring_stiffness>0</spring_stiffness>
        </dynamics>
      </axis>
    </joint>
    <link name='drivewhl_l_link'>
      <pose relative_to='drivewhl_l_joint'>0 0 0 0 -0 0</pose>
      <inertial>
        <pose>0 0 0 1.5708 -0 0</pose>
        <mass>0.5</mass>
        <inertia>
          <ixx>0.00131667</ixx>
          <ixy>0</ixy>
          <ixz>0</ixz>
          <iyy>0.00131667</iyy>
          <iyz>0</iyz>
          <izz>0.0025</izz>
        </inertia>
      </inertial>
      <collision name='drivewhl_l_link_collision'>
        <pose>0 0 0 1.5708 -0 0</pose>
        <geometry>
          <cylinder>
            <length>0.04</length>
            <radius>0.1</radius>
          </cylinder>
        </geometry>
      </collision>
      <visual name='drivewhl_l_link_visual'>
        <pose>0 0 0 1.5708 -0 0</pose>
        <geometry>
          <cylinder>
            <length>0.04</length>
            <radius>0.1</radius>
          </cylinder>
        </geometry>
      </visual>
    </link>
    <joint name='drivewhl_r_joint' type='revolute'>
      <pose relative_to='base_footprint'>-0.12 -0.18 0.1 0 -0 0</pose>
      <parent>base_footprint</parent>
      <child>drivewhl_r_link</child>
      <axis>
        <xyz>0 1 0</xyz>
        <limit>
          <lower>-1e+16</lower>
          <upper>1e+16</upper>
        </limit>
        <dynamics>
          <spring_reference>0</spring_reference>
          <spring_stiffness>0</spring_stiffness>
        </dynamics>
      </axis>
    </joint>
    <link name='drivewhl_r_link'>
      <pose relative_to='drivewhl_r_joint'>0 0 0 0 -0 0</pose>
      <inertial>
        <pose>0 0 0 1.5708 -0 0</pose>
        <mass>0.5</mass>
        <inertia>
          <ixx>0.00131667</ixx>
          <ixy>0</ixy>
          <ixz>0</ixz>
          <iyy>0.00131667</iyy>
          <iyz>0</iyz>
          <izz>0.0025</izz>
        </inertia>
      </inertial>
      <collision name='drivewhl_r_link_collision'>
        <pose>0 0 0 1.5708 -0 0</pose>
        <geometry>
          <cylinder>
            <length>0.04</length>
            <radius>0.1</radius>
          </cylinder>
        </geometry>
      </collision>
      <visual name='drivewhl_r_link_visual'>
        <pose>0 0 0 1.5708 -0 0</pose>
        <geometry>
          <cylinder>
            <length>0.04</length>
            <radius>0.1</radius>
          </cylinder>
        </geometry>
      </visual>
    </link>
    <plugin name='diff_drive' filename='libgazebo_ros_diff_drive.so'>
      <ros/>
      <update_rate>30</update_rate>
      <left_joint>drivewhl_l_joint</left_joint>
      <right_joint>drivewhl_r_joint</right_joint>
      <wheel_separation>0.4</wheel_separation>
      <wheel_diameter>0.2</wheel_diameter>
      <max_wheel_torque>20</max_wheel_torque>
      <max_wheel_acceleration>1.0</max_wheel_acceleration>
      <command_topic>cmd_vel</command_topic>
      <publish_odom>1</publish_odom>
      <publish_odom_tf>1</publish_odom_tf>
      <publish_wheel_tf>1</publish_wheel_tf>
      <odometry_topic>odom</odometry_topic>
      <odometry_frame>odom</odometry_frame>
      <robot_base_frame>base_footprint</robot_base_frame>
    </plugin>
    <plugin name='sambot_joint_state' filename='libgazebo_ros_joint_state_publisher.so'>
      <ros>
        <remapping>~/out:=joint_states</remapping>
      </ros>
      <update_rate>30</update_rate>
      <joint_name>drivewhl_l_joint</joint_name>
      <joint_name>drivewhl_r_joint</joint_name>
    </plugin>
    <frame name='camera_depth_joint' attached_to='camera_link'>
      <pose>0 0 0 -1.5708 -0 -1.5708</pose>
    </frame>
    <frame name='camera_depth_frame' attached_to='camera_depth_joint'/>
    <frame name='camera_joint' attached_to='base_link'>
      <pose>0.215 0 0.05 0 -0 0</pose>
    </frame>
    <frame name='camera_link' attached_to='camera_joint'/>
    <frame name='caster_joint' attached_to='base_link'>
      <pose>0.14 0 -0.09 0 -0 0</pose>
    </frame>
    <frame name='front_caster' attached_to='caster_joint'/>
    <frame name='imu_joint' attached_to='base_link'>
      <pose>0 0 0.01 0 -0 0</pose>
    </frame>
    <frame name='imu_link' attached_to='imu_joint'/>
    <frame name='lidar_joint' attached_to='base_link'>
      <pose>0 0 0.12 0 -0 0</pose>
    </frame>
    <frame name='lidar_link' attached_to='lidar_joint'/>
    <frame name='base_joint' attached_to='base_footprint'>
      <pose>0 0 0.15 0 -0 0</pose>
    </frame>
    <frame name='base_link' attached_to='base_joint'/>
  </model>
</sdf>
