<?xml version="1.0" ?>
<!-- =================================================================================== -->
<!-- |    This document was autogenerated by xacro from sam_bot.xacro                  | -->
<!-- |    EDITING THIS FILE BY HAND IS NOT RECOMMENDED                                 | -->
<!-- =================================================================================== -->
<robot name="sam_bot">
  <!-- Material Definitions -->
  <!-- Init colour -->
  <material name="black">
    <color rgba="0.0 0.0 0.0 1.0"/>
  </material>
  <material name="dark">
    <color rgba="0.3 0.3 0.3 1.0"/>
  </material>
  <material name="light_black">
    <color rgba="0.4 0.4 0.4 1.0"/>
  </material>
  <material name="blue">
    <color rgba="0.0 0.0 0.8 1.0"/>
  </material>
  <material name="green">
    <color rgba="0.0 0.8 0.0 1.0"/>
  </material>
  <material name="grey">
    <color rgba="0.5 0.5 0.5 1.0"/>
  </material>
  <material name="orange">
    <color rgba="1.0 0.4235 0.0392 1.0"/>
  </material>
  <material name="brown">
    <color rgba="0.8706 0.8118 0.7647 1.0"/>
  </material>
  <material name="red">
    <color rgba="0.8 0.0 0.0 1.0"/>
  </material>
  <material name="white">
    <color rgba="1.0 1.0 1.0 1.0"/>
  </material>
  <!-- Calculado na mão-->
  <!-- Fourth Shaft, Rear -->
  <!-- Robot Base -->
  <link name="base_link">
    <visual>
      <geometry>
        <box size="9.605 2.548 0.877"/>
      </geometry>
      <material name="Cyan">
        <color rgba="0 1.0 1.0 1.0"/>
      </material>
    </visual>
    <inertial>
      <origin rpy="1.5707963267948966 0 1.5707963267948966" xyz="0 0 0"/>
      <mass value="500"/>
      <inertia ixx="3876.0480833333336" ixy="0.0" ixz="0.0" iyy="4114.513708333334" iyz="0.0" izz="302.55970833333333"/>
    </inertial>
  </link>
  <!-- Robot Footprint -->
  <link name="base_footprint"/>
  <!--Robot Footprint Visualization-->
  <!-- <link name="base_footprint">
    <visual>
      <origin xyz="0 0 0" rpy="0 0 0"/>
      <geometry> 
        <box size="${base_length} ${base_width} 0.001"/>
      </geometry>
      <material name="red"/>
    </visual>
  </link>  -->
  <joint name="base_joint" type="fixed">
    <parent link="base_link"/>
    <child link="base_footprint"/>
    <origin rpy="0 0 0" xyz="0.0 0.0 -0.877"/>
  </joint>
  <link name="first_shaft_horizontal_shaft_link">
    <visual>
      <geometry>
        <cylinder length="2.573" radius="0.0536"/>
      </geometry>
      <material name="green">
        </material>
      <origin rpy="0 1.5707963267948966 0" xyz="0 0 0"/>
    </visual>
    <collision>
      <geometry>
        <cylinder length="2.548" radius="0.0536"/>
      </geometry>
      <origin rpy="0 1.5707963267948966 0" xyz="0 0 0"/>
    </collision>
    <inertial>
      <origin rpy="0 0 0" xyz="0 0 0"/>
      <mass value="1"/>
      <inertia ixx="0.5417435733333333" ixy="0.0" ixz="0.0" iyy="0.5417435733333333" iyz="0.0" izz="0.0014364800000000002"/>
    </inertial>
  </link>
  <link name="second_shaft_horizontal_shaft_link">
    <visual>
      <geometry>
        <cylinder length="2.573" radius="0.0536"/>
      </geometry>
      <material name="green">
        </material>
      <origin rpy="0 1.5707963267948966 0" xyz="0 0 0"/>
    </visual>
    <collision>
      <geometry>
        <cylinder length="2.548" radius="0.0536"/>
      </geometry>
      <origin rpy="0 1.5707963267948966 0" xyz="0 0 0"/>
    </collision>
    <inertial>
      <origin rpy="0 0 0" xyz="0 0 0"/>
      <mass value="1"/>
      <inertia ixx="0.5417435733333333" ixy="0.0" ixz="0.0" iyy="0.5417435733333333" iyz="0.0" izz="0.0014364800000000002"/>
    </inertial>
  </link>
  <link name="third_shaft_horizontal_shaft_link">
    <visual>
      <geometry>
        <cylinder length="2.573" radius="0.0536"/>
      </geometry>
      <material name="green">
        </material>
      <origin rpy="0 1.5707963267948966 0" xyz="0 0 0"/>
    </visual>
    <collision>
      <geometry>
        <cylinder length="2.548" radius="0.0536"/>
      </geometry>
      <origin rpy="0 1.5707963267948966 0" xyz="0 0 0"/>
    </collision>
    <inertial>
      <origin rpy="0 0 0" xyz="0 0 0"/>
      <mass value="1"/>
      <inertia ixx="0.5417435733333333" ixy="0.0" ixz="0.0" iyy="0.5417435733333333" iyz="0.0" izz="0.0014364800000000002"/>
    </inertial>
  </link>
  <link name="fourth_shaft_horizontal_shaft_link">
    <visual>
      <geometry>
        <cylinder length="2.573" radius="0.0536"/>
      </geometry>
      <material name="green">
        </material>
      <origin rpy="0 1.5707963267948966 0" xyz="0 0 0"/>
    </visual>
    <collision>
      <geometry>
        <cylinder length="2.548" radius="0.0536"/>
      </geometry>
      <origin rpy="0 1.5707963267948966 0" xyz="0 0 0"/>
    </collision>
    <inertial>
      <origin rpy="0 0 0" xyz="0 0 0"/>
      <mass value="1"/>
      <inertia ixx="0.5417435733333333" ixy="0.0" ixz="0.0" iyy="0.5417435733333333" iyz="0.0" izz="0.0014364800000000002"/>
    </inertial>
  </link>
  <joint name="first_shaft_horizontal_shaft_joint" type="fixed">
    <parent link="base_link"/>
    <child link="first_shaft_horizontal_shaft_link"/>
    <origin rpy="0 0 1.5707963267948966" xyz="3.302 0 -0.341"/>
    <axis xyz="0 0 1"/>
    <!-- <limit lower="-0.131" upper="0.131" effort="10000000" velocity="1000000"/> -->
    <!-- Just if change to revolute joint-->
  </joint>
  <joint name="second_shaft_horizontal_shaft_joint" type="fixed">
    <parent link="base_link"/>
    <child link="second_shaft_horizontal_shaft_link"/>
    <origin rpy="0 0 1.5707963267948966" xyz="1.552 0 -0.341"/>
    <axis xyz="0 0 1"/>
    <!-- <limit lower="-0.131" upper="0.131" effort="10000000" velocity="1000000"/> -->
    <!-- Just if change to revolute joint-->
  </joint>
  <joint name="third_shaft_horizontal_shaft_joint" type="fixed">
    <parent link="base_link"/>
    <child link="third_shaft_horizontal_shaft_link"/>
    <origin rpy="0 0 1.5707963267948966" xyz="-2.152 0 -0.341"/>
    <axis xyz="0 0 1"/>
    <!-- <limit lower="-0.131" upper="0.131" effort="10000000" velocity="1000000"/> -->
    <!-- Just if change to revolute joint-->
  </joint>
  <joint name="fourth_shaft_horizontal_shaft_joint" type="fixed">
    <parent link="base_link"/>
    <child link="fourth_shaft_horizontal_shaft_link"/>
    <origin rpy="0 0 1.5707963267948966" xyz="-3.502 0 -0.341"/>
    <axis xyz="0 0 1"/>
    <!-- <limit lower="-0.131" upper="0.131" effort="10000000" velocity="1000000"/> -->
    <!-- Just if change to revolute joint-->
  </joint>
  <link name="front_right_steering_link">
    <visual>
      <geometry>
        <cylinder length="0.5" radius="0.25"/>
      </geometry>
      <material name="white"/>
    </visual>
    <collision>
      <geometry>
        <cylinder length="0.5" radius="0.25"/>
      </geometry>
    </collision>
    <inertial>
      <origin rpy="0 0 0" xyz="0 0 0"/>
      <mass value="2"/>
      <inertia ixx="0.07291666666666666" ixy="0.0" ixz="0.0" iyy="0.07291666666666666" iyz="0.0" izz="0.0625"/>
    </inertial>
  </link>
  <link name="front_left_steering_link">
    <visual>
      <geometry>
        <cylinder length="0.5" radius="0.25"/>
      </geometry>
      <material name="white"/>
    </visual>
    <collision>
      <geometry>
        <cylinder length="0.5" radius="0.25"/>
      </geometry>
    </collision>
    <inertial>
      <origin rpy="0 0 0" xyz="0 0 0"/>
      <mass value="2"/>
      <inertia ixx="0.07291666666666666" ixy="0.0" ixz="0.0" iyy="0.07291666666666666" iyz="0.0" izz="0.0625"/>
    </inertial>
  </link>
  <joint name="front_left_steer_joint" type="revolute">
    <parent link="first_shaft_horizontal_shaft_link"/>
    <child link="front_left_steering_link"/>
    <origin rpy="0 0 0" xyz="1.299 0 -0.001"/>
    <axis xyz="0 0 1"/>
    <limit effort="10000000" lower="-0.524" upper="0.524" velocity="1000000"/>
  </joint>
  <joint name="front_right_steer_joint" type="revolute">
    <parent link="first_shaft_horizontal_shaft_link"/>
    <child link="front_right_steering_link"/>
    <origin rpy="0 0 0" xyz="-1.299 0 -0.001"/>
    <axis xyz="0 0 1"/>
    <limit effort="10000000" lower="-0.524" upper="0.524" velocity="1000000"/>
  </joint>
  <link name="first_wheel_left_link">
    <visual>
      <origin rpy="1.5707963267948966 0 0" xyz="0 0 0"/>
      <geometry>
        <cylinder length="0.385" radius="0.536"/>
      </geometry>
      <material name="Gray">
        <color rgba="0.5 0.5 0.5 1.0"/>
      </material>
    </visual>
    <!-- Add mass and inertia -->
    <!-- Add mass and inertia -->
    <inertial>
      <origin rpy="0 0 0" xyz="0 0 0"/>
      <mass value="74"/>
      <inertia ixx="0.5 * 74 * 0.536 * 0.536" ixy="0" ixz="0" iyy="0.5 * 74 * 0.536 * 0.536" iyz="0" izz="74 * 0.536 * 0.536"/>
    </inertial>
    <collision>
      <geometry>
        <cylinder length="0.385" radius="0.536"/>
      </geometry>
      <origin rpy="1.5707963267948966 0 0" xyz="0 0 0"/>
      <surface>
        <friction>
          <ode>
            <mu>1.0</mu>
            <mu2>1.0</mu2>
            <kp>5000000.0</kp>
            <kd>1.0</kd>
            <fdir1>1 0 0</fdir1>
            <slip1>0.0</slip1>
            <slip2>0.0</slip2>
          </ode>
        </friction>
      </surface>
    </collision>
    <inertial>
      <origin rpy="0 0 0" xyz="0 0 0"/>
      <mass value="74"/>
      <inertia ixx="6.229030166666667" ixy="0.0" ixz="0.0" iyy="6.229030166666667" iyz="0.0" izz="10.629952000000001"/>
    </inertial>
  </link>
  <!-- First and fourth wheels are continuous and children of the steering joints/base link -->
  <joint name="first_wheel_left_joint" type="continuous">
    <parent link="front_left_steering_link"/>
    <origin rpy="0 0 1.57" xyz="0 0 0"/>
    <child link="first_wheel_left_link"/>
    <axis xyz="0 -1 0"/>
  </joint>
  <link name="first_wheel_right_link">
    <visual>
      <origin rpy="1.5707963267948966 0 0" xyz="0 0 0"/>
      <geometry>
        <cylinder length="0.385" radius="0.536"/>
      </geometry>
      <material name="Gray">
        <color rgba="0.5 0.5 0.5 1.0"/>
      </material>
    </visual>
    <!-- Add mass and inertia -->
    <!-- Add mass and inertia -->
    <inertial>
      <origin rpy="0 0 0" xyz="0 0 0"/>
      <mass value="74"/>
      <inertia ixx="0.5 * 74 * 0.536 * 0.536" ixy="0" ixz="0" iyy="0.5 * 74 * 0.536 * 0.536" iyz="0" izz="74 * 0.536 * 0.536"/>
    </inertial>
    <collision>
      <geometry>
        <cylinder length="0.385" radius="0.536"/>
      </geometry>
      <origin rpy="1.5707963267948966 0 0" xyz="0 0 0"/>
      <surface>
        <friction>
          <ode>
            <mu>1.0</mu>
            <mu2>1.0</mu2>
            <kp>5000000.0</kp>
            <kd>1.0</kd>
            <fdir1>1 0 0</fdir1>
            <slip1>0.0</slip1>
            <slip2>0.0</slip2>
          </ode>
        </friction>
      </surface>
    </collision>
    <inertial>
      <origin rpy="0 0 0" xyz="0 0 0"/>
      <mass value="74"/>
      <inertia ixx="6.229030166666667" ixy="0.0" ixz="0.0" iyy="6.229030166666667" iyz="0.0" izz="10.629952000000001"/>
    </inertial>
  </link>
  <!-- First and fourth wheels are continuous and children of the steering joints/base link -->
  <joint name="first_wheel_right_joint" type="continuous">
    <parent link="front_right_steering_link"/>
    <origin rpy="0 0 1.57" xyz="0 0 0"/>
    <child link="first_wheel_right_link"/>
    <axis xyz="0 -1 0"/>
  </joint>
  <link name="second_wheel_left_link">
    <visual>
      <origin rpy="1.5707963267948966 0 0" xyz="0 0 0"/>
      <geometry>
        <cylinder length="0.385" radius="0.536"/>
      </geometry>
      <material name="Gray">
        <color rgba="0.5 0.5 0.5 1.0"/>
      </material>
    </visual>
    <!-- Add mass and inertia -->
    <!-- Add mass and inertia -->
    <inertial>
      <origin rpy="0 0 0" xyz="0 0 0"/>
      <mass value="74"/>
      <inertia ixx="0.5 * 74 * 0.536 * 0.536" ixy="0" ixz="0" iyy="0.5 * 74 * 0.536 * 0.536" iyz="0" izz="74 * 0.536 * 0.536"/>
    </inertial>
    <collision>
      <geometry>
        <cylinder length="0.385" radius="0.536"/>
      </geometry>
      <origin rpy="1.5707963267948966 0 0" xyz="0 0 0"/>
      <surface>
        <friction>
          <ode>
            <mu>0.2</mu>
            <mu2>0.2</mu2>
            <kp>1000000.0</kp>
            <kd>0.5</kd>
            <fdir1>1 0 0</fdir1>
            <slip1>0.0</slip1>
            <slip2>0.0</slip2>
          </ode>
        </friction>
      </surface>
    </collision>
    <inertial>
      <origin rpy="0 0 0" xyz="0 0 0"/>
      <mass value="74"/>
      <inertia ixx="6.229030166666667" ixy="0.0" ixz="0.0" iyy="6.229030166666667" iyz="0.0" izz="10.629952000000001"/>
    </inertial>
  </link>
  <!-- Second and third wheels are fixed type and children of respective shafts -->
  <joint name="second_wheel_left_joint" type="fixed">
    <parent link="second_shaft_horizontal_shaft_link"/>
    <child link="second_wheel_left_link"/>
    <origin rpy="0 0 1.57" xyz="1.299 0 0"/>
  </joint>
  <link name="second_wheel_right_link">
    <visual>
      <origin rpy="1.5707963267948966 0 0" xyz="0 0 0"/>
      <geometry>
        <cylinder length="0.385" radius="0.536"/>
      </geometry>
      <material name="Gray">
        <color rgba="0.5 0.5 0.5 1.0"/>
      </material>
    </visual>
    <!-- Add mass and inertia -->
    <!-- Add mass and inertia -->
    <inertial>
      <origin rpy="0 0 0" xyz="0 0 0"/>
      <mass value="74"/>
      <inertia ixx="0.5 * 74 * 0.536 * 0.536" ixy="0" ixz="0" iyy="0.5 * 74 * 0.536 * 0.536" iyz="0" izz="74 * 0.536 * 0.536"/>
    </inertial>
    <collision>
      <geometry>
        <cylinder length="0.385" radius="0.536"/>
      </geometry>
      <origin rpy="1.5707963267948966 0 0" xyz="0 0 0"/>
      <surface>
        <friction>
          <ode>
            <mu>0.2</mu>
            <mu2>0.2</mu2>
            <kp>1000000.0</kp>
            <kd>0.5</kd>
            <fdir1>1 0 0</fdir1>
            <slip1>0.0</slip1>
            <slip2>0.0</slip2>
          </ode>
        </friction>
      </surface>
    </collision>
    <inertial>
      <origin rpy="0 0 0" xyz="0 0 0"/>
      <mass value="74"/>
      <inertia ixx="6.229030166666667" ixy="0.0" ixz="0.0" iyy="6.229030166666667" iyz="0.0" izz="10.629952000000001"/>
    </inertial>
  </link>
  <!-- Second and third wheels are fixed type and children of respective shafts -->
  <joint name="second_wheel_right_joint" type="fixed">
    <parent link="second_shaft_horizontal_shaft_link"/>
    <child link="second_wheel_right_link"/>
    <origin rpy="0 0 1.57" xyz="-1.299 0 0"/>
  </joint>
  <link name="third_wheel_left_link">
    <visual>
      <origin rpy="1.5707963267948966 0 0" xyz="0 0 0"/>
      <geometry>
        <cylinder length="0.385" radius="0.536"/>
      </geometry>
      <material name="Gray">
        <color rgba="0.5 0.5 0.5 1.0"/>
      </material>
    </visual>
    <!-- Add mass and inertia -->
    <!-- Add mass and inertia -->
    <inertial>
      <origin rpy="0 0 0" xyz="0 0 0"/>
      <mass value="74"/>
      <inertia ixx="0.5 * 74 * 0.536 * 0.536" ixy="0" ixz="0" iyy="0.5 * 74 * 0.536 * 0.536" iyz="0" izz="74 * 0.536 * 0.536"/>
    </inertial>
    <collision>
      <geometry>
        <cylinder length="0.385" radius="0.536"/>
      </geometry>
      <origin rpy="1.5707963267948966 0 0" xyz="0 0 0"/>
      <surface>
        <friction>
          <ode>
            <mu>0.2</mu>
            <mu2>0.2</mu2>
            <kp>1000000.0</kp>
            <kd>0.5</kd>
            <fdir1>1 0 0</fdir1>
            <slip1>0.0</slip1>
            <slip2>0.0</slip2>
          </ode>
        </friction>
      </surface>
    </collision>
    <inertial>
      <origin rpy="0 0 0" xyz="0 0 0"/>
      <mass value="74"/>
      <inertia ixx="6.229030166666667" ixy="0.0" ixz="0.0" iyy="6.229030166666667" iyz="0.0" izz="10.629952000000001"/>
    </inertial>
  </link>
  <!-- Second and third wheels are fixed type and children of respective shafts -->
  <joint name="third_wheel_left_joint" type="fixed">
    <parent link="third_shaft_horizontal_shaft_link"/>
    <child link="third_wheel_left_link"/>
    <origin rpy="0 0 1.57" xyz="1.299 0 0"/>
  </joint>
  <link name="third_wheel_right_link">
    <visual>
      <origin rpy="1.5707963267948966 0 0" xyz="0 0 0"/>
      <geometry>
        <cylinder length="0.385" radius="0.536"/>
      </geometry>
      <material name="Gray">
        <color rgba="0.5 0.5 0.5 1.0"/>
      </material>
    </visual>
    <!-- Add mass and inertia -->
    <!-- Add mass and inertia -->
    <inertial>
      <origin rpy="0 0 0" xyz="0 0 0"/>
      <mass value="74"/>
      <inertia ixx="0.5 * 74 * 0.536 * 0.536" ixy="0" ixz="0" iyy="0.5 * 74 * 0.536 * 0.536" iyz="0" izz="74 * 0.536 * 0.536"/>
    </inertial>
    <collision>
      <geometry>
        <cylinder length="0.385" radius="0.536"/>
      </geometry>
      <origin rpy="1.5707963267948966 0 0" xyz="0 0 0"/>
      <surface>
        <friction>
          <ode>
            <mu>0.2</mu>
            <mu2>0.2</mu2>
            <kp>1000000.0</kp>
            <kd>0.5</kd>
            <fdir1>1 0 0</fdir1>
            <slip1>0.0</slip1>
            <slip2>0.0</slip2>
          </ode>
        </friction>
      </surface>
    </collision>
    <inertial>
      <origin rpy="0 0 0" xyz="0 0 0"/>
      <mass value="74"/>
      <inertia ixx="6.229030166666667" ixy="0.0" ixz="0.0" iyy="6.229030166666667" iyz="0.0" izz="10.629952000000001"/>
    </inertial>
  </link>
  <!-- Second and third wheels are fixed type and children of respective shafts -->
  <joint name="third_wheel_right_joint" type="fixed">
    <parent link="third_shaft_horizontal_shaft_link"/>
    <child link="third_wheel_right_link"/>
    <origin rpy="0 0 1.57" xyz="-1.299 0 0"/>
  </joint>
  <link name="fourth_wheel_left_link">
    <visual>
      <origin rpy="1.5707963267948966 0 0" xyz="0 0 0"/>
      <geometry>
        <cylinder length="0.385" radius="0.536"/>
      </geometry>
      <material name="Gray">
        <color rgba="0.5 0.5 0.5 1.0"/>
      </material>
    </visual>
    <!-- Add mass and inertia -->
    <!-- Add mass and inertia -->
    <inertial>
      <origin rpy="0 0 0" xyz="0 0 0"/>
      <mass value="74"/>
      <inertia ixx="0.5 * 74 * 0.536 * 0.536" ixy="0" ixz="0" iyy="0.5 * 74 * 0.536 * 0.536" iyz="0" izz="74 * 0.536 * 0.536"/>
    </inertial>
    <collision>
      <geometry>
        <cylinder length="0.385" radius="0.536"/>
      </geometry>
      <origin rpy="1.5707963267948966 0 0" xyz="0 0 0"/>
      <surface>
        <friction>
          <ode>
            <mu>1.0</mu>
            <mu2>1.0</mu2>
            <kp>5000000.0</kp>
            <kd>1.0</kd>
            <fdir1>1 0 0</fdir1>
            <slip1>0.0</slip1>
            <slip2>0.0</slip2>
          </ode>
        </friction>
      </surface>
    </collision>
    <inertial>
      <origin rpy="0 0 0" xyz="0 0 0"/>
      <mass value="74"/>
      <inertia ixx="6.229030166666667" ixy="0.0" ixz="0.0" iyy="6.229030166666667" iyz="0.0" izz="10.629952000000001"/>
    </inertial>
  </link>
  <!-- First and fourth wheels are continuous and children of the steering joints/base link -->
  <joint name="fourth_wheel_left_joint" type="continuous">
    <parent link="fourth_shaft_horizontal_shaft_link"/>
    <origin rpy="0 0 1.57" xyz="1.299 0 0"/>
    <child link="fourth_wheel_left_link"/>
    <axis xyz="0 -1 0"/>
  </joint>
  <link name="fourth_wheel_right_link">
    <visual>
      <origin rpy="1.5707963267948966 0 0" xyz="0 0 0"/>
      <geometry>
        <cylinder length="0.385" radius="0.536"/>
      </geometry>
      <material name="Gray">
        <color rgba="0.5 0.5 0.5 1.0"/>
      </material>
    </visual>
    <!-- Add mass and inertia -->
    <!-- Add mass and inertia -->
    <inertial>
      <origin rpy="0 0 0" xyz="0 0 0"/>
      <mass value="74"/>
      <inertia ixx="0.5 * 74 * 0.536 * 0.536" ixy="0" ixz="0" iyy="0.5 * 74 * 0.536 * 0.536" iyz="0" izz="74 * 0.536 * 0.536"/>
    </inertial>
    <collision>
      <geometry>
        <cylinder length="0.385" radius="0.536"/>
      </geometry>
      <origin rpy="1.5707963267948966 0 0" xyz="0 0 0"/>
      <surface>
        <friction>
          <ode>
            <mu>1.0</mu>
            <mu2>1.0</mu2>
            <kp>5000000.0</kp>
            <kd>1.0</kd>
            <fdir1>1 0 0</fdir1>
            <slip1>0.0</slip1>
            <slip2>0.0</slip2>
          </ode>
        </friction>
      </surface>
    </collision>
    <inertial>
      <origin rpy="0 0 0" xyz="0 0 0"/>
      <mass value="74"/>
      <inertia ixx="6.229030166666667" ixy="0.0" ixz="0.0" iyy="6.229030166666667" iyz="0.0" izz="10.629952000000001"/>
    </inertial>
  </link>
  <!-- First and fourth wheels are continuous and children of the steering joints/base link -->
  <joint name="fourth_wheel_right_joint" type="continuous">
    <parent link="fourth_shaft_horizontal_shaft_link"/>
    <origin rpy="0 0 1.57" xyz="-1.299 0 0"/>
    <child link="fourth_wheel_right_link"/>
    <axis xyz="0 -1 0"/>
  </joint>
  <gazebo>
    <plugin filename="libgazebo_ros_ackermann_drive.so" name="ackermann_drive">
      <ros>
        <!-- <namespace>/demo</namespace> -->
        <parameter name="cmd_vel_topic" value="cmd_vel"/>
        <parameter name="odom_topic" value="odom"/>
        <parameter name="distance_topic" value="distance"/>
      </ros>
      <update_rate>100.0</update_rate>
      <!-- wheels -->
      <front_left_joint>first_wheel_left_joint</front_left_joint>
      <front_right_joint>first_wheel_right_joint</front_right_joint>
      <rear_left_joint>fourth_wheel_left_joint</rear_left_joint>
      <rear_right_joint>fourth_wheel_right_joint</rear_right_joint>
      <left_steering_joint>front_left_steer_joint</left_steering_joint>
      <right_steering_joint>front_right_steer_joint</right_steering_joint>
      <!-- Max absolute steer angle for tyre in radians-->
      <!-- Any cmd_vel angular z greater than this would be capped -->
      <max_steer>0.6458</max_steer>
      <!-- Max absolute steering angle of steering wheel -->
      <max_steering_angle>7.85</max_steering_angle>
      <!-- Max absolute linear speed in m/s -->
      <max_speed>20</max_speed>
      <!-- PID tuning -->
      <left_steering_pid_gain>1500 0 1</left_steering_pid_gain>
      <left_steering_i_range>0 0</left_steering_i_range>
      <right_steering_pid_gain>1500 0 1</right_steering_pid_gain>
      <right_steering_i_range>0 0</right_steering_i_range>
      <linear_velocity_pid_gain>1000 0 1</linear_velocity_pid_gain>
      <linear_velocity_i_range>0 0</linear_velocity_i_range>
      <!-- output -->
      <publish_odom>true</publish_odom>
      <publish_odom_tf>true</publish_odom_tf>
      <publish_wheel_tf>true</publish_wheel_tf>
      <publish_distance>true</publish_distance>
      <odometry_frame>odom</odometry_frame>
      <robot_base_frame>base_footprint</robot_base_frame>
    </plugin>
  </gazebo>
</robot>
